<?xml version = "1.0"?>
<robot name="Riggu" xmlns:xacro="https://ros.org/wiki/xacro">

  <!-- Defining the robot constants -->
  <xacro:property name="base_length" value="0.31"/>
  <xacro:property name="base_width" value="0.34"/>
  <xacro:property name="base_height" value="0.07"/>

  <xacro:property name="wheel_radius" value="0.065"/>
  <xacro:property name="wheel_length" value="0.065"/>
  <xacro:property name="wheel_ygap" value="0.0"/>
  <xacro:property name="wheel_zoff" value="0.03"/>
  <xacro:property name="wheel_xoff" value="0.105"/>

  <xacro:property name="caster_off" value="0.1"/>

  <xacro:property name="lidar_radius" value="0.035"/>
  <xacro:property name="lidar_height" value="0.055"/>

  <!-- Robot base -->
  <link name="base_link">
    <visual>
      <geometry>
        <box size="${base_width} ${base_length} ${base_height}"/>
      </geometry>
      <material name="Cyan">
        <color rgba="0 1 1 1"/>
      </material>
    </visual>
  </link>

  <!-- Robot Footprint -->
  <link name="base_footprint"/>

  <joint name="base_joint" type="fixed">
    <parent link="base_link"/>
    <child link="base_footprint"/>
    <origin xyz="0 0 ${wheel_radius+wheel_zoff}" rpy="0 0 0"/>
  </joint>

  <!-- Wheels -->
  <xacro:macro name="wheel" params="prefix x_reflect y_reflect">
    <link name="${prefix}_link">
      <visual>
        <origin xyz="0 0 0" rpy="${pi/2} 0 0"/>
        <geometry>
          <cylinder radius="${wheel_radius}" length="${wheel_length}"/>
        </geometry>
        <material name="Gray">
          <color rgba="0.5 0.5 0.5 1"/>
        </material>
      </visual>
    </link>

    <joint name="${prefix}_joint" type="continuous">
      <parent link="base_link"/>
      <child link="${prefix}_link"/>
      <origin xyz="${x_reflect*wheel_xoff} ${y_reflect*(base_width/2+wheel_ygap)} ${-wheel_zoff}" rpy="0 0 0"/>
      <axis xyz="0 1 0"/>
    </joint>
  </xacro:macro>

  <xacro:wheel prefix="left_wheel" x_reflect="-1" y_reflect="1"/>
  <xacro:wheel prefix="right_wheel" x_reflect="-1" y_reflect="-1"/>

  <!-- Caster Wheel -->
  <link name="front_caster">
    <visual>
      <geometry>
        <sphere radius="${wheel_radius+wheel_zoff-(base_height/2)}"/>
      </geometry>
      <material name="Cyan">
        <color rgba="0 1 1 1"/>
      </material>
    </visual>
  </link>

  <joint name="caster_joint" type="fixed">
    <parent link="base_link"/>
    <child link="front_caster"/>
    <origin xyz="${caster_off} 0 ${-base_height/2}" rpy="0 0 0"/>
  </joint>

  <!-- Lidar -->
  <link name="laser">
    <visual>
      <geometry>
        <cylinder radius="${lidar_radius}" length="${lidar_height}"/>
      </geometry>
      <material name="Red">
        <color rgba="1 0 0 1"/>
      </material>
    </visual>
  </link>

  <joint name="laser_joint" type="fixed">
    <parent link="base_link"/>
    <child link="laser"/>
    <origin xyz="0 0 ${base_height/2}" rpy="0 0 3.14"/>
  </joint>

  <!-- Gazebo Plugins -->

  <!-- Differential Drive Plugin -->
  <gazebo>
    <plugin name="gazebo_ros_diff_drive" filename="libgazebo_ros_diff_drive.so">
      <ros>
        <namespace>/</namespace>
        <remapping>odom:=/odom</remapping>
      </ros>
      <updateRate>50</updateRate>
      <left_joint>left_wheel_joint</left_joint>
      <right_joint>right_wheel_joint</right_joint>
      <wheel_separation>${base_width}</wheel_separation>
      <wheel_diameter>${wheel_radius*2}</wheel_diameter>
      <robot_base_frame>base_link</robot_base_frame>
      <odom_frame>odom</odom_frame>
      <cmd_vel_topic>/cmd_vel</cmd_vel_topic>
      <odometry_topic>/odom</odometry_topic>
    </plugin>
  </gazebo>

  <!-- LIDAR Plugin -->
  <gazebo>
    <plugin name="gazebo_ros_laser" filename="libgazebo_ros_laser.so">
      <topicName>/scan</topicName>
      <frameName>laser</frameName>
    </plugin>
  </gazebo>

  <!-- IMU Sensor Plugin (optional) -->
  <gazebo>
    <plugin name="gazebo_ros_imu" filename="libgazebo_ros_imu.so">
      <alwaysOn>true</alwaysOn>
      <updateRate>50</updateRate>
      <bodyName>base_link</bodyName>
      <topicName>imu</topicName>
    </plugin>
  </gazebo>

</robot>
