<?xml version="1.0"?>
<!--
  Gazebo ROS differential drive plugin demo

  Try sending commands:

    ros2 topic pub /demo/cmd_demo geometry_msgs/Twist '{linear: {x: 1.0}}' -1

    ros2 topic pub /demo/cmd_demo geometry_msgs/Twist '{angular: {z: 0.1}}' -1

  Try listening to odometry:

    ros2 topic echo /demo/odom_demo

  Try listening to TF:

    ros2 run tf2_ros tf2_echo odom_demo base_link

    ros2 run tf2_ros tf2_echo base_link right_wheel

    ros2 run tf2_ros tf2_echo base_link left_wheel
-->
<sdf version="1.6">
  <world name="default">

    <include>
      <uri>model://ground_plane</uri>
    </include>

    <include>
      <uri>model://sun</uri>
    </include>

    <model name='vehicle'>
      <pose>0 0 0.325 0 -0 0</pose>

      <link name='base_link'>
      <pose>0 0 0.0 0.105 0 0 0</pose>

        <inertial>
          <mass>1.14395</mass>
          <inertia>
            <ixx>0.126164</ixx>
            <ixy>0</ixy>
            <ixz>0</ixz>
            <iyy>0.416519</iyy>
            <iyz>0</iyz>
            <izz>0.481014</izz>
          </inertia>
        </inertial>
        <visual name='visual'>
          <geometry>
            <box>
              <size>0.31 0.34 0.07</size>
            </box>
          </geometry>
        </visual>
        <collision name='collision'>
          <geometry>
            <box>
              <size>0.31 0.34 0.07</size>
            </box>
          </geometry>
        </collision>
      </link>

      <link name='left_wheel'>
      <pose>0.2 0.105 -0.005 0 1.57 0</pose>
        <inertial>
          <mass>2</mass>
          <inertia>
            <ixx>0.145833</ixx>
            <ixy>0</ixy>
            <ixz>0</ixz>
            <iyy>0.145833</iyy>
            <iyz>0</iyz>
            <izz>0.125</izz>
          </inertia>
        </inertial>
        <visual name='visual'>
          <geometry>
            <cylinder>
              <length>0.09</length>
              <radius>0.065</radius>
            </cylinder>
          </geometry>
        </visual>
        <collision name='collision'>
          <geometry>
            <cylinder>
              <length>0.09</length>
              <radius>0.065</radius>
            </cylinder>
          </geometry>
          <surface>
            <friction>
              <ode>
                <mu>1</mu>
                <mu2>1</mu2>
                <slip1>0</slip1>
                <slip2>0</slip2>
              </ode>
            </friction>
            <contact>
              <ode>
                <soft_cfm>0</soft_cfm>
                <soft_erp>0.2</soft_erp>
                <kp>1e+13</kp>
                <kd>1</kd>
                <max_vel>0.01</max_vel>
                <min_depth>0.01</min_depth>
              </ode>
            </contact>
          </surface>
        </collision>
      </link>

      <link name='right_wheel'>
      <pose>-0.2 0.105 -0.005 0 1.57 0</pose>
        <inertial>
          <mass>2</mass>
          <inertia>
            <ixx>0.145833</ixx>
            <ixy>0</ixy>
            <ixz>0</ixz>
            <iyy>0.145833</iyy>
            <iyz>0</iyz>
            <izz>0.125</izz>
          </inertia>
        </inertial>
        <visual name='visual'>
          <geometry>
            <cylinder>
              <length>0.09</length>
              <radius>0.065</radius>
            </cylinder>
          </geometry>
        </visual>
        <collision name='collision'>
          <geometry>
            <cylinder>
              <length>0.09</length>
              <radius>0.065</radius>
            </cylinder>
          </geometry>
          <surface>
            <friction>
              <ode>
                <mu>1</mu>
                <mu2>1</mu2>
                <slip1>0</slip1>
                <slip2>0</slip2>
              </ode>
            </friction>
            <contact>
              <ode>
                <soft_cfm>0</soft_cfm>
                <soft_erp>0.2</soft_erp>
                <kp>1e+13</kp>
                <kd>1</kd>
                <max_vel>0.01</max_vel>
                <min_depth>0.01</min_depth>
              </ode>
            </contact>
          </surface>
        </collision>
      </link>

      <link name='caster'>
      <pose>0 -0.12 -0.05 0 0 0</pose>
        <inertial>
          <mass>1</mass>
          <inertia>
            <ixx>0.1</ixx>
            <ixy>0</ixy>
            <ixz>0</ixz>
            <iyy>0.1</iyy>
            <iyz>0</iyz>
            <izz>0.1</izz>
          </inertia>
        </inertial>
        <visual name='visual'>
          <geometry>
            <sphere>
              <radius>0.045</radius>
            </sphere>
          </geometry>
        </visual>
        <collision name='collision'>
          <geometry>
            <sphere>
              <radius>0.045</radius>
            </sphere>
          </geometry>
        </collision>
      </link>

    <link name='imu_link'>
      <pose>0 0.0 0.035 0 0 0</pose>
      <inertial>
          <mass>1</mass>
          <inertia>
            <ixx>0.1</ixx>
            <ixy>0</ixy>
            <ixz>0</ixz>
            <iyy>0.1</iyy>
            <iyz>0</iyz>
            <izz>0.1</izz>
          </inertia>
        </inertial>
        <visual name='visual'>
          <geometry>
            <box>
              <size>0.05 0.05 0.05</size>
            </box>
          </geometry>
        </visual>
    </link>

      <joint name='left_wheel_joint' type='revolute'>
        <parent>base_link</parent>
        <child>left_wheel</child>
        <origin xyz="0.245 0.04 0.0" rpy="0.0 0.0 0.0"/>
        <axis>
          <xyz>0 0 1</xyz>
          <limit>
            <lower>-1.79769e+308</lower>
            <upper>1.79769e+308</upper>
          </limit>
        </axis>
      </joint>

      <joint name='right_wheel_joint' type='revolute'>
        <parent>base_link</parent>
        <child>right_wheel</child>
        <origin xyz="-0.245 0.04 0.0" rpy="0.0 0.0 0.0"/>
        <axis>
          <xyz>0 0 1</xyz>
          <limit>
            <lower>-1.79769e+308</lower>
            <upper>1.79769e+308</upper>
          </limit>
        </axis>
      </joint>

      <joint name='caster_wheel' type='ball'>
        <origin xyz="0 0 -0.06" rpy="0 0 0"/>
        <parent>base_link</parent>
        <child>caster</child>
      </joint>

       <joint name='imu' type='fixed'>
        <origin xyz="0 0 0.035" rpy="0 0 0"/>
        <parent>base_link</parent>
        <child>imu</child>
      </joint>

      <plugin name='diff_drive' filename='libgazebo_ros_diff_drive.so'>


        <!-- wheels -->
        <left_joint>left_wheel_joint</left_joint>
        <right_joint>right_wheel_joint</right_joint>

        <!-- kinematics -->
        <wheel_separation>0.36</wheel_separation>
        <wheel_diameter>0.13</wheel_diameter>

        <!-- limits -->
        <max_wheel_torque>20</max_wheel_torque>
        <max_wheel_acceleration>1.0</max_wheel_acceleration>

        <!-- output -->
        <publish_odom>true</publish_odom>
        <publish_odom_tf>true</publish_odom_tf>
        <publish_wheel_tf>true</publish_wheel_tf>

        <odometry_frame>odom</odometry_frame>
        <robot_base_frame>base_link</robot_base_frame>

      </plugin>

    </model>

  </world>
</sdf>
