<?xml version="1.0"?>
<robot name="diff_drive_bot" xmlns:xacro="http://ros.org/wiki/xacro">

<xacro property="length" value="0.31"/>
<xacro property="breadth" value="0.34"/>
<xacro property="height" value="0.14"/>

<xacro:property name="wheel_radius" value="0.13"/>
<xacro:property name="wheel_separation" value="0.49"/>
<xacro:property name="wheel_width" value="0.065"/>
<xacro:property name="wheel2base" value="0.09"/>

<link name="base_link">
  <visual>
    <geometry>
      <box size="${length} ${breadth} ${height} "/>
    </geometry>
  </visual>
  <collision>
    <geometry>
      <box size="${length} ${breadth} ${height} "/>
    </geometry>
  </collision>
  <inertial>
    <mass value="1"/>
    <inertia ixx="0.1" ixy="0" ixz="0" iyy="0.1" iyz="0" izz="0.1"/>
  </inertial>
</link>


<link name="left_wheel">
  <visual>
    <geometry>
      <cylinder length="${wheel2base}" radius="${wheel_radius}"/>
    </geometry>
  </visual>
</link>

<link name="right_wheel">
  <visual>
    <geometry>
      <cylinder length="${wheel2base}" radius="${wheel_radius}"/>
    </geometry>
  </visual>
</link>


<joint name="left_wheel_joint" type="continuous">
  <parent link="base_link"/>
  <child link="left_wheel"/>
  <origin xyz="0.0 0.0 {height}" rpy="0 0 0"/>
  <axis xyz="0 1 0"/>
</joint>

<joint name="right_wheel_joint" type="continuous">
  <parent link="base_link"/>
  <child link="right_wheel"/>
  <origin xyz="0.0 0.15 0.0" rpy="0 0 0"/>
  <axis xyz="0 1 0"/>
</joint>

<joint name="imu_link" type="fixed">
  <parent link="base_link"/>
  <child link="imu"/>
  <origin xyz="0.0 0.0 ${height}" rpy="0 0 0"/>
</joint>
    
</robot>