<?xml version="1.0" ?>
<!-- =================================================================================== -->
<!-- |    This document was autogenerated by xacro from /home/rahul/Desktop/riggu_ws/install/riggu_nav2/share/riggu_nav2/urdf/riggu_simulation.xacro | -->
<!-- |    EDITING THIS FILE BY HAND IS NOT RECOMMENDED                                 | -->
<!-- =================================================================================== -->
<robot name="Riggu">
  <!-- Robot base -->
  <link name="base_link">
    <visual>
      <geometry>
        <box size="0.34 0.31 0.07"/>
      </geometry>
      <material name="Cyan">
        <color rgba="0 1 1 1"/>
      </material>
    </visual>
  </link>
  <!-- Robot Footprint -->
  <link name="base_footprint"/>
  <joint name="base_joint" type="fixed">
    <parent link="base_link"/>
    <child link="base_footprint"/>
    <origin rpy="0 0 0" xyz="0 0 0.095"/>
  </joint>
  <link name="left_wheel_link">
    <visual>
      <origin rpy="1.5707963267948966 0 0" xyz="0 0 0"/>
      <geometry>
        <cylinder length="0.065" radius="0.065"/>
      </geometry>
      <material name="Gray">
        <color rgba="0.5 0.5 0.5 1"/>
      </material>
    </visual>
  </link>
  <joint name="left_wheel_joint" type="continuous">
    <parent link="base_link"/>
    <child link="left_wheel_link"/>
    <origin rpy="0 0 0" xyz="-0.105 0.17 -0.03"/>
    <axis xyz="0 1 0"/>
  </joint>
  <link name="right_wheel_link">
    <visual>
      <origin rpy="1.5707963267948966 0 0" xyz="0 0 0"/>
      <geometry>
        <cylinder length="0.065" radius="0.065"/>
      </geometry>
      <material name="Gray">
        <color rgba="0.5 0.5 0.5 1"/>
      </material>
    </visual>
  </link>
  <joint name="right_wheel_joint" type="continuous">
    <parent link="base_link"/>
    <child link="right_wheel_link"/>
    <origin rpy="0 0 0" xyz="-0.105 -0.17 -0.03"/>
    <axis xyz="0 1 0"/>
  </joint>
  <!-- Caster Wheel -->
  <link name="front_caster">
    <visual>
      <geometry>
        <sphere radius="0.06"/>
      </geometry>
      <material name="Cyan">
        <color rgba="0 1 1 1"/>
      </material>
    </visual>
  </link>
  <joint name="caster_joint" type="fixed">
    <parent link="base_link"/>
    <child link="front_caster"/>
    <origin rpy="0 0 0" xyz="0.1 0 -0.035"/>
  </joint>
  <!-- Lidar -->
  <link name="laser">
    <visual>
      <geometry>
        <cylinder length="0.055" radius="0.035"/>
      </geometry>
      <material name="Red">
        <color rgba="1 0 0 1"/>
      </material>
    </visual>
  </link>
  <joint name="laser_joint" type="fixed">
    <parent link="base_link"/>
    <child link="laser"/>
    <origin rpy="0 0 3.14" xyz="0 0 0.035"/>
  </joint>
  <!-- Gazebo Plugins -->
  <!-- Differential Drive Plugin -->
  <gazebo>
    <plugin filename="libgazebo_ros_diff_drive.so" name="gazebo_ros_diff_drive">
      <ros>
        <namespace>/</namespace>
        <remapping>odom:=/odom</remapping>
      </ros>
      <updateRate>50</updateRate>
      <left_joint>left_wheel_joint</left_joint>
      <right_joint>right_wheel_joint</right_joint>
      <wheel_separation>0.34</wheel_separation>
      <wheel_diameter>0.13</wheel_diameter>
      <robot_base_frame>base_link</robot_base_frame>
      <odom_frame>odom</odom_frame>
      <cmd_vel_topic>/cmd_vel</cmd_vel_topic>
      <odometry_topic>/odom</odometry_topic>
    </plugin>
  </gazebo>
  <!-- LIDAR Plugin -->
  <gazebo>
    <plugin filename="libgazebo_ros_laser.so" name="gazebo_ros_laser">
      <topicName>/scan</topicName>
      <frameName>laser</frameName>
    </plugin>
  </gazebo>
  <!-- IMU Sensor Plugin (optional) -->
  <gazebo>
    <plugin filename="libgazebo_ros_imu.so" name="gazebo_ros_imu">
      <alwaysOn>true</alwaysOn>
      <updateRate>50</updateRate>
      <bodyName>base_link</bodyName>
      <topicName>imu</topicName>
    </plugin>
  </gazebo>
</robot>
